Workbook

Sheet data
A1: memberID | B1: first_event | C1: most_recent_year | D1: count | E1: most_recent_college | F1: code
A2: 2178 | B2: 1975 | C2: 1996 | D2: 4 | E2: UC Santa Cruz | F2: nonCaCC
A3: 1968 | B3: 1979 | C3: 2016 | D3: 7 | E3: Menlo College (CA) | F3: nonCaCC
A4: 2117 | B4: 1979 | C4: 2004 | D4: 3 | E4: Nassau CC (NY) | F4: nonCaCC
A5: 2138 | B5: 1979 | C5: 1981 | D5: 3 | E5: CSU Sacramento | F5: nonCaCC
A6: 1420 | B6: 2002 | C6: 2017 | D6: 14 | E6: Sierra College | F6: retired
A7: 2090 | B7: 1980 | C7: 1998 | D7: 2 | E7: Cerritos College, U. Colorado Denver | F7: multiple
A8: 1156 | B8: 1984 | C8: 2008 | D8: 10 | E8: San Joaquin Delta College, De Anza College | F8: multiple
A9: 2262 | B9: 1985 | C9: 2006 | D9: 4 | E9: Los Angeles Pierce College, CSU Northridge | F9: multiple
A10: 2097 | B10: 1991 | C10: 1998 | D10: 4 | E10: College of Alameda, City College of San Francisco | F10: multiple
A11: 2058 | B11: 2017 | C11: 2017 | D11: 2 | E11: Lake Tahoe C C student | F11: student
A12: 1606 | B12: 2008 | C12: 2008 | D12: 1 | E12: (none) | F12: skip
A13: 1346 | B13: 1993 | C13: 2012 | D13: 8 | E13: Las Positas College, Chabot College | F13: multiple
... A312: 1971 | B312: 2016 | C312: 2017 | D312: 2 | E312: (none) | F312: skip
A313: 1349 | B313: 1994 | C313: 2008 | D313: 2 | E313: Allan Hancock College
A314: 1869 | B314: 2007 | C314: 2007 | D314: 1 | E314: Allan Hancock College
A315: 1176 | B315: 2008 | C315: 2009 | D315: 2 | E315: Allan Hancock College
A316: 1657 | B316: 2010 | C316: 2013 | D316: 3 | E316: Allan Hancock College
A317: 1659 | B317: 2013 | C317: 2013 | D317: 1 | E317: Allan Hancock College
A318: 1655 | B318: 2013 | C318: 2016 | D318: 2 | E318: Allan Hancock College
A319: 1658 | B319: 2013 | C319: 2016 | D319: 2 | E319: Allan Hancock College
A320: 1451 | B320: 2014 | C320: 2015 | D320: 2 | E320: Allan Hancock College
A321: 2055 | B321: 2016 | C321: 2016 | D321: 1 | E321: Allan Hancock College
A322: 1144 | B322: 1972 | C322: 2016 | D322: 16 | E322: American River College
A323: 2185 | B323: 1981 | C323: 1981 | D323: 1 | E323: American River College
A324: 1130 | B324: 1990 | C324: 2010 | D324: 11 | E324: American River College
... A1266: 1953 | B1266: 2015 | C1266: 2015 | D1266: 1 | E1266: Yuba College
D1267: =SUM(D2:D1266) -> 5517 | E1267: grand total attendance, from 1265 people
D1268: events per person avg. = | E1268: =D1267/1265 -> 4.3612648
A1270: memberID | B1270: first_event | C1270: most_recent_year | D1270: count | E1270: most_recent_college | F1270: code

Sheet stats
A1: assumed linear decrease from 2018 to 1972 = | B1: 0.15 | C1: per 47 years
A3: CA_CC | B3: potential_in_1972 | C3: potential_in_2018 | D3: potential___total | E3: total_attendance_all_years | F3: proportion_of_filled_potential | G3: miles_to_dirive
A4: Santa Rosa Junior College | B4: =ROUND(B$1*C4,0) -> 9 | C4: =_xlfn.XLOOKUP(A4,[1]Sheet1!$B$2:$B$115,[1]Sheet1!$F$2:$F$115) -> 57 | D4: =ROUND(47*B4*(B$1+1)/(2*B$1),0) -> 1622 | E4: =SUMIF(data!$E$313:$E$1266,stats!A4,data!$D$313:$D$1266) -> 468 | F4: =E4/D4 -> 0.28853268 | G4: 171
A5: Solano Community College | B5: =ROUND(B$1*C5,0) -> 4 | C5: =_xlfn.XLOOKUP(A5,[1]Sheet1!$B$2:$B$115,[1]Sheet1!$F$2:$F$115) -> 26 | D5: =ROUND(47*B5*(B$1+1)/(2*B$1),0) -> 721 | E5: =SUMIF(data!$E$313:$E$1266,stats!A5,data!$D$313:$D$1266) -> 166 | F5: =E5/D5 -> 0.23023578 | G5: 142
A6: Columbia College | B6: =ROUND(B$1*C6,0) -> 1 | C6: =_xlfn.XLOOKUP(A6,[1]Sheet1!$B$2:$B$115,[1]Sheet1!$F$2:$F$115) -> 9 | D6: =ROUND(47*B6*(B$1+1)/(2*B$1),0) -> 180 | E6: =SUMIF(data!$E$313:$E$1266,stats!A6,data!$D$313:$D$1266) -> 39 | F6: =E6/D6 -> 0.21666667 | G6: 180
A7: Lake Tahoe Community College | B7: =ROUND(B$1*C7,0) -> 2 | C7: =_xlfn.XLOOKUP(A7,[1]Sheet1!$B$2:$B$115,[1]Sheet1!$F$2:$F$115) -> 11 | D7: =ROUND(47*B7*(B$1+1)/(2*B$1),0) -> 360 | E7: =SUMIF(data!$E$313:$E$1266,stats!A7,data!$D$313:$D$1266) -> 68 | F7: =E7/D7 -> 0.18888889 | G7: 287
A8: Mission College | B8: =ROUND(B$1*C8,0) -> 5 | C8: =_xlfn.XLOOKUP(A8,[1]Sheet1!$B$2:$B$115,[1]Sheet1!$F$2:$F$115) -> 35 | D8: =ROUND(47*B8*(B$1+1)/(2*B$1),0) -> 901 | E8: =SUMIF(data!$E$313:$E$1266,stats!A8,data!$D$313:$D$1266) -> 162 | F8: =E8/D8 -> 0.17980022 | G8: 79
A9: West Valley College | B9: =ROUND(B$1*C9,0) -> 5 | C9: =_xlfn.XLOOKUP(A9,[1]Sheet1!$B$2:$B$115,[1]Sheet1!$F$2:$F$115) -> 31 | D9: =ROUND(47*B9*(B$1+1)/(2*B$1),0) -> 901 | E9: =SUMIF(data!$E$313:$E$1266,stats!A9,data!$D$313:$D$1266) -> 156 | F9: =E9/D9 -> 0.17314095 | G9: 65
A10: Chabot College | B10: =ROUND(B$1*C10,0) -> 5 | C10: =_xlfn.XLOOKUP(A10,[1]Sheet1!$B$2:$B$115,[1]Sheet1!$F$2:$F$115) -> 36 | D10: =ROUND(47*B10*(B$1+1)/(2*B$1),0) -> 901 | E10: =SUMIF(data!$E$313:$E$1266,stats!A10,data!$D$313:$D$1266) -> 141 | F10: =E10/D10 -> 0.15649279 | G10: 97
A11: De Anza College | B11: =ROUND(B$1*C11,0) -> 12 | C11: =_xlfn.XLOOKUP(A11,[1]Sheet1!$B$2:$B$115,[1]Sheet1!$F$2:$F$115) -> 81 | D11: =ROUND(47*B11*(B$1+1)/(2*B$1),0) -> 2162 | E11: =SUMIF(data!$E$313:$E$1266,stats!A11,data!$D$313:$D$1266) -> 326 | F11: =E11/D11 -> 0.15078631 | G11: 71
A12: Modesto Junior College | B12: =ROUND(B$1*C12,0) -> 5 | C12: =_xlfn.XLOOKUP(A12,[1]Sheet1!$B$2:$B$115,[1]Sheet1!$F$2:$F$115) -> 33 | D12: =ROUND(47*B12*(B$1+1)/(2*B$1),0) -> 901 | E12: =SUMIF(data!$E$313:$E$1266,stats!A12,data!$D$313:$D$1266) -> 134 | F12: =E12/D12 -> 0.14872364 | G12: 128
A13: Evergreen Valley College | B13: =ROUND(B$1*C13,0) -> 4 | C13: =_xlfn.XLOOKUP(A13,[1]Sheet1!$B$2:$B$115,[1]Sheet1!$F$2:$F$115) -> 25 | D13: =ROUND(47*B13*(B$1+1)/(2*B$1),0) -> 721 | E13: =SUMIF(data!$E$313:$E$1266,stats!A13,data!$D$313:$D$1266) -> 88 | F13: =E13/D13 -> 0.1220527 | G13: 70
A14: Foothill College | B14: =ROUND(B$1*C14,0) -> 4 | C14: =_xlfn.XLOOKUP(A14,[1]Sheet1!$B$2:$B$115,[1]Sheet1!$F$2:$F$115) -> 28 | D14: =ROUND(47*B14*(B$1+1)/(2*B$1),0) -> 721 | E14: =SUMIF(data!$E$313:$E$1266,stats!A14,data!$D$313:$D$1266) -> 85 | F14: =E14/D14 -> 0.11789182 | G14: 77
A15: Sacramento City College | B15: =ROUND(B$1*C15,0) -> 10 | C15: =_xlfn.XLOOKUP(A15,[1]Sheet1!$B$2:$B$115,[1]Sheet1!$F$2:$F$115) -> 68 | D15: =ROUND(47*B15*(B$1+1)/(2*B$1),0) -> 1802 | E15: =SUMIF(data!$E$313:$E$1266,stats!A15,data!$D$313:$D$1266) -> 211 | F15: =E15/D15 -> 0.11709212 | G15: 189
... A100: El Camino College | B100: =ROUND(B$1*C100,0) -> 21 | C100: =_xlfn.XLOOKUP(A100,[1]Sheet1!$B$2:$B$115,[1]Sheet1!$F$2:$F$115) -> 139 | D100: =ROUND(47*B100*(B$1+1)/(2*B$1),0) -> 3784 | E100: =SUMIF(data!$E$313:$E$1266,stats!A100,data!$D$313:$D$1266) -> 1 | F100: =E100/D100 -> 0.00026427061 | G100: 330
C101: =SUM(C4:C100) -> 4153 | E101: =SUM(E4:E100) -> 4635
B103: number of people not included in the above data: | F103: total attendance not included above
B104: 9 | C104: attendees from unknown locations | F104: 11
B105: 266 | C105: students or non-CA CC faculty | F105: 682
B106: 26 | C106: faculty at multiple locations | F106: 110
B107: 10 | C107: retirees | F107: 79
B108: =SUM(B104:B107) -> 311 | C108: total | F108: =SUM(F104:F107) -> 882 | G108: total
E109: =E101 -> 4635
E110: =F108 -> 882
E111: =SUM(E109:E110) -> 5517 | F111: grand total attendance
A112: zero attendance as of 2018 from: | C112: potential_from_2018
A113: Barstow College | C113: 18
A114: Compton College | C114: 20
A115: Copper Mountain College | C115: 14
A116: Crafton Hills College | C116: 15
A117: Cypress College | C117: 61
A118: Long Beach City College | C118: 30
A119: Los Angeles City College | C119: 32
A120: Los Angeles Harbor College | C120: 17
A121: Los Angeles Mission College | C121: 42
A122: Los Angeles Southwest College | C122: 18
A123: Los Angeles Trade Tech College | C123: 28
A124: Moorpark College | C124: 61
... A129: West Hills College Lemoore | C129: 12
A131: 97 + 17 = 114 community colleges in CA total
...

Sheet viz

Sheet src
A1: source = attendance_db . xlsx
A3: =ISNUMBER(MATCH(A2, '[potential by college 2019 Feb.xlsx]Sheet1'!$B$2:$B$115,0))
